<?xml version="1.0" encoding="utf-8"?>
<!-- This URDF was automatically created by SolidWorks to URDF Exporter! Originally created by Stephen Brawner (brawner@gmail.com) 
     Commit Version: 1.6.0-4-g7f85cfe  Build Version: 1.6.7995.38578
     For more information, please see http://wiki.ros.org/sw_urdf_exporter -->
<robot
  name="car_claw">
  <link
    name="base_link">
    <inertial>
      <origin
        xyz="0.0098883 -0.0014336 0.0084774"
        rpy="0 0 0" />
      <mass
        value="0.03" />
      <inertia
        ixx="3.0956E-08"
        ixy="-6.4103E-13"
        ixz="1.985E-24"
        iyy="7.893E-08"
        iyz="2.1787E-26"
        izz="4.8852E-08" />
    </inertial>
    <visual>
      <origin
        xyz="0 0 0"
        rpy="0 0 0" />
      <geometry>
        <mesh
          filename="./meshes/base_link.STL" />
      </geometry>
      <material
        name="">
        <color
          rgba="1 1 1 1" />
      </material>
    </visual>
    <collision>
      <origin
        xyz="0 0 0"
        rpy="0 0 0" />
      <geometry>
        <mesh
          filename="./meshes/base_link.STL" />
      </geometry>
    </collision>
  </link>
  <link
    name="left_wheel_link">
    <inertial>
      <origin
        xyz="4.669E-08 -1.8476E-08 -0.0025"
        rpy="0 0 0" />
      <mass
        value="0.003" />
      <inertia
        ixx="8.0361E-09"
        ixy="1.9004E-14"
        ixz="2.8303E-14"
        iyy="8.0392E-09"
        iyz="-2.7469E-14"
        izz="1.2978E-08" />
    </inertial>
    <visual>
      <origin
        xyz="0 0 0"
        rpy="0 0 0" />
      <geometry>
        <mesh
          filename="./meshes/left_wheel_link.STL" />
      </geometry>
      <material
        name="">
        <color
          rgba="1 1 1 1" />
      </material>
    </visual>
    <collision>
      <origin
        xyz="0 0 0"
        rpy="0 0 0" />
      <geometry>
        <mesh
          filename="./meshes/left_wheel_link.STL" />
      </geometry>
    </collision>
  </link>
  <joint
    name="left_wheel_joint"
    type="continuous">
    <origin
      xyz="0.018473718935328 0.00252262291644261 -0.00254"
      rpy="1.5707963267949 -0.151670996045839 0" />
    <parent
      link="base_link" />
    <child
      link="left_wheel_link" />
    <axis
      xyz="0 0 1" />
  </joint>
  <link
    name="right_wheel_link">
    <inertial>
      <origin
        xyz="4.669E-08 -1.8476E-08 0.0025"
        rpy="0 0 0" />
      <mass
        value="0.003" />
      <inertia
        ixx="8.0361E-09"
        ixy="1.9004E-14"
        ixz="2.8303E-14"
        iyy="8.0392E-09"
        iyz="-2.7469E-14"
        izz="1.2978E-08" />
    </inertial>
    <visual>
      <origin
        xyz="0 0 0"
        rpy="0 0 0" />
      <geometry>
        <mesh
          filename="./meshes/right_wheel_link.STL" />
      </geometry>
      <material
        name="">
        <color
          rgba="1 1 1 1" />
      </material>
    </visual>
    <collision>
      <origin
        xyz="0 0 0"
        rpy="0 0 0" />
      <geometry>
        <mesh
          filename="./meshes/right_wheel_link.STL" />
      </geometry>
    </collision>
  </link>
  <joint
    name="right_wheel_joint"
    type="continuous">
    <origin
      xyz="0.018473718935328 -0.0194773770835574 -0.00254"
      rpy="1.5707963267949 1.41912533074906 0" />
    <parent
      link="base_link" />
    <child
      link="right_wheel_link" />
    <axis
      xyz="0 0 1" />
  </joint>
  <link
    name="rear_wheel_link">
    <inertial>
      <origin
        xyz="0 0 0.001"
        rpy="0 0 0" />
      <mass
        value="0.001" />
      <inertia
        ixx="1.378E-11"
        ixy="4.039E-28"
        ixz="8.3588E-29"
        iyy="1.378E-11"
        iyz="-4.8718E-28"
        izz="1.7481E-11" />
    </inertial>
    <visual>
      <origin
        xyz="0 0 0"
        rpy="0 0 0" />
      <geometry>
        <mesh
          filename="./meshes/rear_wheel_link.STL" />
      </geometry>
      <material
        name="">
        <color
          rgba="1 1 1 1" />
      </material>
    </visual>
    <collision>
      <origin
        xyz="0 0 0"
        rpy="0 0 0" />
      <geometry>
        <mesh
          filename="./meshes/rear_wheel_link.STL" />
      </geometry>
    </collision>
  </link>
  <joint
    name="rear_wheel_joint"
    type="continuous">
    <origin
      xyz="-0.0189262810646719 -0.00747737708355739 -0.000300000000000001"
      rpy="-1.5707963267949 1.3896408065705 -3.14159265358979" />
    <parent
      link="base_link" />
    <child
      link="rear_wheel_link" />
    <axis
      xyz="0 0 1" />
  </joint>
</robot>